2017-03-05 14:35:43,909 ERROR: [<Article 'タイトル1'>, <Article 'タイトル2'>] [in main.py:18]
2017-03-05 14:36:34,128 ERROR: [<Article 'タイトル1'>, <Article 'タイトル2'>] [in main.py:18]
2017-03-05 14:45:11,085 ERROR: [<Article 'タイトル1'>, <Article 'タイトル2'>] [in main.py:19]
2017-03-05 14:45:58,347 ERROR: Exception on / [GET] [in /usr/local/lib/python3.6/site-packages/flask/app.py:1560]
Traceback (most recent call last):
  File "/usr/local/lib/python3.6/site-packages/sqlalchemy/pool.py", line 1122, in _do_get
    return self._pool.get(wait, self._timeout)
  File "/usr/local/lib/python3.6/site-packages/sqlalchemy/util/queue.py", line 145, in get
    raise Empty
sqlalchemy.util.queue.Empty

During handling of the above exception, another exception occurred:

Traceback (most recent call last):
  File "/usr/local/lib/python3.6/site-packages/sqlalchemy/engine/base.py", line 2138, in _wrap_pool_connect
    return fn()
  File "/usr/local/lib/python3.6/site-packages/sqlalchemy/pool.py", line 387, in connect
    return _ConnectionFairy._checkout(self)
  File "/usr/local/lib/python3.6/site-packages/sqlalchemy/pool.py", line 766, in _checkout
    fairy = _ConnectionRecord.checkout(pool)
  File "/usr/local/lib/python3.6/site-packages/sqlalchemy/pool.py", line 516, in checkout
    rec = pool._do_get()
  File "/usr/local/lib/python3.6/site-packages/sqlalchemy/pool.py", line 1138, in _do_get
    self._dec_overflow()
  File "/usr/local/lib/python3.6/site-packages/sqlalchemy/util/langhelpers.py", line 60, in __exit__
    compat.reraise(exc_type, exc_value, exc_tb)
  File "/usr/local/lib/python3.6/site-packages/sqlalchemy/util/compat.py", line 187, in reraise
    raise value
  File "/usr/local/lib/python3.6/site-packages/sqlalchemy/pool.py", line 1135, in _do_get
    return self._create_connection()
  File "/usr/local/lib/python3.6/site-packages/sqlalchemy/pool.py", line 333, in _create_connection
    return _ConnectionRecord(self)
  File "/usr/local/lib/python3.6/site-packages/sqlalchemy/pool.py", line 461, in __init__
    self.__connect(first_connect_check=True)
  File "/usr/local/lib/python3.6/site-packages/sqlalchemy/pool.py", line 651, in __connect
    connection = pool._invoke_creator(self)
  File "/usr/local/lib/python3.6/site-packages/sqlalchemy/engine/strategies.py", line 105, in connect
    return dialect.connect(*cargs, **cparams)
  File "/usr/local/lib/python3.6/site-packages/sqlalchemy/engine/default.py", line 393, in connect
    return self.dbapi.connect(*cargs, **cparams)
  File "/usr/local/lib/python3.6/site-packages/pymysql/__init__.py", line 90, in Connect
    return Connection(*args, **kwargs)
  File "/usr/local/lib/python3.6/site-packages/pymysql/connections.py", line 699, in __init__
    self.connect()
  File "/usr/local/lib/python3.6/site-packages/pymysql/connections.py", line 928, in connect
    self._request_authentication()
  File "/usr/local/lib/python3.6/site-packages/pymysql/connections.py", line 1148, in _request_authentication
    auth_packet = self._read_packet()
  File "/usr/local/lib/python3.6/site-packages/pymysql/connections.py", line 1010, in _read_packet
    packet.check_error()
  File "/usr/local/lib/python3.6/site-packages/pymysql/connections.py", line 393, in check_error
    err.raise_mysql_exception(self._data)
  File "/usr/local/lib/python3.6/site-packages/pymysql/err.py", line 107, in raise_mysql_exception
    raise errorclass(errno, errval)
pymysql.err.OperationalError: (1044, "Access denied for user 'news'@'%' to database 'new'")

The above exception was the direct cause of the following exception:

Traceback (most recent call last):
  File "/usr/local/lib/python3.6/site-packages/flask/app.py", line 1982, in wsgi_app
    response = self.full_dispatch_request()
  File "/usr/local/lib/python3.6/site-packages/flask/app.py", line 1614, in full_dispatch_request
    rv = self.handle_user_exception(e)
  File "/usr/local/lib/python3.6/site-packages/flask/app.py", line 1517, in handle_user_exception
    reraise(exc_type, exc_value, tb)
  File "/usr/local/lib/python3.6/site-packages/flask/_compat.py", line 33, in reraise
    raise value
  File "/usr/local/lib/python3.6/site-packages/flask/app.py", line 1612, in full_dispatch_request
    rv = self.dispatch_request()
  File "/usr/local/lib/python3.6/site-packages/flask/app.py", line 1598, in dispatch_request
    return self.view_functions[rule.endpoint](**req.view_args)
  File "main.py", line 13, in index
    articles = Article.query.all()
  File "/usr/local/lib/python3.6/site-packages/sqlalchemy/orm/query.py", line 2638, in all
    return list(self)
  File "/usr/local/lib/python3.6/site-packages/sqlalchemy/orm/query.py", line 2790, in __iter__
    return self._execute_and_instances(context)
  File "/usr/local/lib/python3.6/site-packages/sqlalchemy/orm/query.py", line 2811, in _execute_and_instances
    close_with_result=True)
  File "/usr/local/lib/python3.6/site-packages/sqlalchemy/orm/query.py", line 2820, in _get_bind_args
    **kw
  File "/usr/local/lib/python3.6/site-packages/sqlalchemy/orm/query.py", line 2802, in _connection_from_session
    conn = self.session.connection(**kw)
  File "/usr/local/lib/python3.6/site-packages/sqlalchemy/orm/session.py", line 966, in connection
    execution_options=execution_options)
  File "/usr/local/lib/python3.6/site-packages/sqlalchemy/orm/session.py", line 971, in _connection_for_bind
    engine, execution_options)
  File "/usr/local/lib/python3.6/site-packages/sqlalchemy/orm/session.py", line 403, in _connection_for_bind
    conn = bind.contextual_connect()
  File "/usr/local/lib/python3.6/site-packages/sqlalchemy/engine/base.py", line 2103, in contextual_connect
    self._wrap_pool_connect(self.pool.connect, None),
  File "/usr/local/lib/python3.6/site-packages/sqlalchemy/engine/base.py", line 2142, in _wrap_pool_connect
    e, dialect, self)
  File "/usr/local/lib/python3.6/site-packages/sqlalchemy/engine/base.py", line 1456, in _handle_dbapi_exception_noconnection
    exc_info
  File "/usr/local/lib/python3.6/site-packages/sqlalchemy/util/compat.py", line 203, in raise_from_cause
    reraise(type(exception), exception, tb=exc_tb, cause=cause)
  File "/usr/local/lib/python3.6/site-packages/sqlalchemy/util/compat.py", line 186, in reraise
    raise value.with_traceback(tb)
  File "/usr/local/lib/python3.6/site-packages/sqlalchemy/engine/base.py", line 2138, in _wrap_pool_connect
    return fn()
  File "/usr/local/lib/python3.6/site-packages/sqlalchemy/pool.py", line 387, in connect
    return _ConnectionFairy._checkout(self)
  File "/usr/local/lib/python3.6/site-packages/sqlalchemy/pool.py", line 766, in _checkout
    fairy = _ConnectionRecord.checkout(pool)
  File "/usr/local/lib/python3.6/site-packages/sqlalchemy/pool.py", line 516, in checkout
    rec = pool._do_get()
  File "/usr/local/lib/python3.6/site-packages/sqlalchemy/pool.py", line 1138, in _do_get
    self._dec_overflow()
  File "/usr/local/lib/python3.6/site-packages/sqlalchemy/util/langhelpers.py", line 60, in __exit__
    compat.reraise(exc_type, exc_value, exc_tb)
  File "/usr/local/lib/python3.6/site-packages/sqlalchemy/util/compat.py", line 187, in reraise
    raise value
  File "/usr/local/lib/python3.6/site-packages/sqlalchemy/pool.py", line 1135, in _do_get
    return self._create_connection()
  File "/usr/local/lib/python3.6/site-packages/sqlalchemy/pool.py", line 333, in _create_connection
    return _ConnectionRecord(self)
  File "/usr/local/lib/python3.6/site-packages/sqlalchemy/pool.py", line 461, in __init__
    self.__connect(first_connect_check=True)
  File "/usr/local/lib/python3.6/site-packages/sqlalchemy/pool.py", line 651, in __connect
    connection = pool._invoke_creator(self)
  File "/usr/local/lib/python3.6/site-packages/sqlalchemy/engine/strategies.py", line 105, in connect
    return dialect.connect(*cargs, **cparams)
  File "/usr/local/lib/python3.6/site-packages/sqlalchemy/engine/default.py", line 393, in connect
    return self.dbapi.connect(*cargs, **cparams)
  File "/usr/local/lib/python3.6/site-packages/pymysql/__init__.py", line 90, in Connect
    return Connection(*args, **kwargs)
  File "/usr/local/lib/python3.6/site-packages/pymysql/connections.py", line 699, in __init__
    self.connect()
  File "/usr/local/lib/python3.6/site-packages/pymysql/connections.py", line 928, in connect
    self._request_authentication()
  File "/usr/local/lib/python3.6/site-packages/pymysql/connections.py", line 1148, in _request_authentication
    auth_packet = self._read_packet()
  File "/usr/local/lib/python3.6/site-packages/pymysql/connections.py", line 1010, in _read_packet
    packet.check_error()
  File "/usr/local/lib/python3.6/site-packages/pymysql/connections.py", line 393, in check_error
    err.raise_mysql_exception(self._data)
  File "/usr/local/lib/python3.6/site-packages/pymysql/err.py", line 107, in raise_mysql_exception
    raise errorclass(errno, errval)
sqlalchemy.exc.OperationalError: (pymysql.err.OperationalError) (1044, "Access denied for user 'news'@'%' to database 'new'")
2017-03-05 14:46:06,252 ERROR: [<Article 'タイトル1'>, <Article 'タイトル2'>] [in main.py:17]
